#VRML_SIM R2025a utf8
# license: Apache License 2.0
# license url: http://www.apache.org/licenses/LICENSE-2.0
# This is a proto file for Webots for the Go2
# Extracted from: /home/skpawar1305/ros2_ws/go2.urdf

EXTERNPROTO "https://raw.githubusercontent.com/cyberbotics/webots/R2025a/projects/devices/velodyne/protos/VelodynePuck.proto"
EXTERNPROTO "../Omx/Omx.proto"

PROTO Go2 [
  field  SFVec3f     translation     0 0 0
  field  SFRotation  rotation        0 0 1 0
  field  SFString    name            "Go2"  # Is `Robot.name`.
  field  SFString    controller      "void" # Is `Robot.controller`.
  field  MFString    controllerArgs  []     # Is `Robot.controllerArgs`.
  field  SFString    customData      ""     # Is `Robot.customData`.
  field  SFBool      supervisor      FALSE  # Is `Robot.supervisor`.
  field  SFBool      synchronization TRUE   # Is `Robot.synchronization`.
  field  SFBool      selfCollision   FALSE  # Is `Robot.selfCollision`.
  field  SFVec3f     omx_translation     0 0 0.05
  field  SFRotation  omx_rotation        0 0 1 0
] {
  Robot {
    translation IS translation
    rotation IS rotation
    controller IS controller
    controllerArgs IS controllerArgs
    customData IS customData
    supervisor IS supervisor
    synchronization IS synchronization
    selfCollision IS selfCollision
    physics Physics {
      density -1
      mass 0.001000
      centerOfMass [ 0.000000 0.000000 0.000000 ]
      inertiaMatrix [
        1.000000e-04 1.000000e-04 1.000000e-04
        0.000000e+00 0.000000e+00 0.000000e+00
      ]
    }
    children [
      Transform {
        translation 0.2 0 0.07
        children [
          Omx {
            name "Omx"
            controller "<extern>"
          }
        ]
      }
      InertialUnit {
      }
      Gyro {
      }
      Accelerometer {
      }
      GPS {
      }
      Shape {
        appearance PBRAppearance {
          baseColor 0.500000 0.500000 0.500000
          roughness 1.000000
          metalness 0
        }
        geometry Box {
           size 0.001000 0.001000 0.001000
        }
      }
      VelodynePuck {
        translation 0 0 0.09
        name "Velodyne_Puck"
      }
      Solid {
        translation 0.250000 -0.038000 -0.030000
        rotation 0.704149 0.703941 0.092960 2.956152
        children [
          DEF L1_4D_Lidar_visual CadShape {
            url "meshes/L1_4D_Lidar.dae"
          }
        ]
        name "lidar_l1_link"
        boundingObject DEF L1_4D_Lidar Mesh {
          url "meshes/L1_4D_Lidar.dae"
        }
        physics Physics {
          density -1
          mass 0.500000
          centerOfMass [ 0.000000 0.000000 0.000000 ]
          inertiaMatrix [
            1.000000e-02 1.000000e-02 1.000000e-02
            0.000000e+00 0.000000e+00 0.000000e+00
          ]
        }
      }
      Solid {
        children [
          DEF trunk_visual CadShape {
            url "meshes/trunk.dae"
          }
          Solid {
            children [
              Shape {
                appearance PBRAppearance {
                  baseColor 0.500000 0.500000 0.500000
                  roughness 1.000000
                  metalness 0
                }
                geometry Box {
                   size 0.001000 0.001000 0.001000
                }
              }
            ]
            name "imu_link"
            boundingObject Box {
               size 0.001000 0.001000 0.001000
            }
            physics Physics {
              density -1
              mass 0.001000
              centerOfMass [ 0.000000 0.000000 0.000000 ]
              inertiaMatrix [
                1.000000e-04 1.000000e-04 1.000000e-04
                0.000000e+00 0.000000e+00 0.000000e+00
              ]
            }
          }
          Solid {
            translation 0.326000 0.000000 0.043000
            children [
              Shape {
                appearance DEF camera_link_material PBRAppearance {
                  baseColor 0.500000 0.000000 0.000000
                  roughness 1.000000
                  metalness 0
                }
                geometry Sphere {
                  radius 0.001
                }
              }
              Pose {
                translation 0 0 0
                children [
                  Camera {
                    name "rgb_camera"
                    fieldOfView 1.367000
                    width 640
                    height 480
                  }
                ]
              }
            ]
            name "camera_link"
            boundingObject Sphere {
              radius 0.001
            }
            physics Physics {
              density -1
              mass 0.001000
              centerOfMass [ 0.000000 0.000000 0.000000 ]
              inertiaMatrix [
                1.000000e-04 1.000000e-04 1.000000e-04
                0.000000e+00 0.000000e+00 0.000000e+00
              ]
            }
          }
          HingeJoint {
            jointParameters HingeJointParameters {
              anchor 0.193400 -0.046500 0.000000
              dampingConstant 0.01
              staticFriction 0.2
            }
            device [
              RotationalMotor {
                name "rf_hip_joint"
                maxVelocity 30.1
                minPosition -1.0472
                maxPosition 1.0472
                maxTorque 23.7
              }
              PositionSensor {
                name "rf_hip_joint_sensor"
              }
            ]
            endPoint Solid {
              translation 0.193400 -0.046500 0.000000
              children [
                Pose {
                  rotation 1.000000 0.000000 0.000000 3.141593
                  children [
                    DEF hip_visual CadShape {
                      url "meshes/hip.dae"
                    }
                  ]
                }
                HingeJoint {
                  jointParameters HingeJointParameters {
                    axis 0.000000 1.000000 0.000000
                    anchor 0.000000 -0.095500 0.000000
                    dampingConstant 0.01
                    staticFriction 0.2
                  }
                  device [
                    RotationalMotor {
                      name "rf_upper_leg_joint"
                      maxVelocity 30.1
                      minPosition -1.5708
                      maxPosition 3.4907
                      maxTorque 23.7
                    }
                    PositionSensor {
                      name "rf_upper_leg_joint_sensor"
                    }
                  ]
                  endPoint Solid {
                    translation 0.000000 -0.095500 0.000000
                    children [
                      DEF thigh_mirror_visual CadShape {
                        url "meshes/thigh_mirror.dae"
                      }
                      HingeJoint {
                        jointParameters HingeJointParameters {
                          position -1.780230
                          axis 0.000000 1.000000 0.000000
                          anchor 0.000000 0.000000 -0.213000
                          dampingConstant 0.01
                          staticFriction 0.2
                        }
                        device [
                          RotationalMotor {
                            name "rf_lower_leg_joint"
                            maxVelocity 20.06
                            minPosition -2.7227
                            maxPosition -0.83776
                            maxTorque 35.55
                          }
                          PositionSensor {
                            name "rf_lower_leg_joint_sensor"
                          }
                        ]
                        endPoint Solid {
                          translation 0.000000 0.000000 -0.213000
                          rotation 0.000000 -1.000000 0.000000 1.780230
                          children [
                            DEF calf_visual CadShape {
                              url "meshes/calf.dae"
                            }
                            Solid {
                              translation 0.000000 0.000000 -0.213000
                              children [
                                Shape {
                                  appearance PBRAppearance {
                                    baseColor 0.500000 0.500000 0.500000
                                    roughness 1.000000
                                    metalness 0
                                  }
                                  geometry Sphere {
                                    radius 0.01
                                  }
                                }
                              ]
                              name "rf_foot_link"
                              boundingObject Sphere {
                                radius 0.02
                              }
                              physics Physics {
                                density -1
                                mass 0.060000
                                centerOfMass [ 0.000000 0.000000 0.000000 ]
                                inertiaMatrix [
                                  9.600000e-06 9.600000e-06 9.600000e-06
                                  0.000000e+00 0.000000e+00 0.000000e+00
                                ]
                              }
                            }
                          ]
                          name "rf_lower_leg_link"
                          boundingObject Transform {
                            translation 0 0 -0.1
                            rotation 0 1 0 1.570796
                            children [
                              Box {
                                size 0.213000 0.016000 0.016000
                              }
                            ]
                          }
                          physics Physics {
                            density -1
                            mass 0.154000
                            centerOfMass [ 0.005480 -0.000975 -0.115000 ]
                            inertiaMatrix [
                              1.080000e-03 1.100000e-03 3.290000e-05
                              3.400000e-07 1.720000e-05 8.280000e-06
                            ]
                          }
                        }
                      }
                    ]
                    name "rf_upper_leg_link"
                    boundingObject Transform {
                      translation 0 0 -0.1
                      rotation 0 1 0 1.570796
                      children [
                        Box {
                          size 0.213000 0.024500 0.034000
                        }
                      ]
                    }
                    physics Physics {
                      density -1
                      mass 1.152000
                      centerOfMass [ -0.003740 0.022300 -0.032700 ]
                      inertiaMatrix [
                        5.840000e-03 5.800000e-03 1.030000e-03
                        -8.720000e-05 -2.890000e-04 -8.080000e-04
                      ]
                    }
                  }
                }
              ]
              name "rf_hip_link"
              boundingObject Transform {
                rotation 1 0 0 1.570796
                children [
                  Cylinder {
                    radius 0.046
                    height 0.04
                  }
                ]
              }
              physics Physics {
                density -1
                mass 0.678000
                centerOfMass [ -0.005400 -0.001940 -0.000105 ]
                inertiaMatrix [
                  4.800000e-04 8.840000e-04 5.960000e-04
                  3.010000e-06 1.110000e-06 1.420000e-06
                ]
              }
            }
          }
          HingeJoint {
            jointParameters HingeJointParameters {
              anchor 0.193400 0.046500 0.000000
              dampingConstant 0.01
              staticFriction 0.2
            }
            device [
              RotationalMotor {
                name "lf_hip_joint"
                maxVelocity 30.1
                minPosition -1.0472
                maxPosition 1.0472
                maxTorque 23.7
              }
              PositionSensor {
                name "lf_hip_joint_sensor"
              }
            ]
            endPoint Solid {
              translation 0.193400 0.046500 0.000000
              children [
                USE hip_visual
                HingeJoint {
                  jointParameters HingeJointParameters {
                    axis 0.000000 1.000000 0.000000
                    anchor 0.000000 0.095500 0.000000
                    dampingConstant 0.01
                    staticFriction 0.2
                  }
                  device [
                    RotationalMotor {
                      name "lf_upper_leg_joint"
                      maxVelocity 30.1
                      minPosition -1.5708
                      maxPosition 3.4907
                      maxTorque 23.7
                    }
                    PositionSensor {
                      name "lf_upper_leg_joint_sensor"
                    }
                  ]
                  endPoint Solid {
                    translation 0.000000 0.095500 0.000000
                    children [
                      DEF thigh_visual CadShape {
                        url "meshes/thigh.dae"
                      }
                      HingeJoint {
                        jointParameters HingeJointParameters {
                          position -1.780230
                          axis 0.000000 1.000000 0.000000
                          anchor 0.000000 0.000000 -0.213000
                          dampingConstant 0.01
                          staticFriction 0.2
                        }
                        device [
                          RotationalMotor {
                            name "lf_lower_leg_joint"
                            maxVelocity 20.06
                            minPosition -2.7227
                            maxPosition -0.83776
                            maxTorque 35.55
                          }
                          PositionSensor {
                            name "lf_lower_leg_joint_sensor"
                          }
                        ]
                        endPoint Solid {
                          translation 0.000000 0.000000 -0.213000
                          rotation 0.000000 -1.000000 0.000000 1.780230
                          children [
                            USE calf_visual
                            Solid {
                              translation 0.000000 0.000000 -0.213000
                              children [
                                Shape {
                                  appearance PBRAppearance {
                                    baseColor 0.500000 0.500000 0.500000
                                    roughness 1.000000
                                    metalness 0
                                  }
                                  geometry Sphere {
                                    radius 0.01
                                  }
                                }
                              ]
                              name "lf_foot_link"
                              boundingObject Sphere {
                                radius 0.02
                              }
                              physics Physics {
                                density -1
                                mass 0.060000
                                centerOfMass [ 0.000000 0.000000 0.000000 ]
                                inertiaMatrix [
                                  9.600000e-06 9.600000e-06 9.600000e-06
                                  0.000000e+00 0.000000e+00 0.000000e+00
                                ]
                              }
                            }
                          ]
                          name "lf_lower_leg_link"
                          boundingObject Transform {
                            translation 0 0 -0.1
                            rotation 0 1 0 1.570796
                            children [
                              Box {
                                size 0.213000 0.016000 0.016000
                              }
                            ]
                          }
                          physics Physics {
                            density -1
                            mass 0.154000
                            centerOfMass [ 0.005480 -0.000975 -0.115000 ]
                            inertiaMatrix [
                              1.080000e-03 1.100000e-03 3.290000e-05
                              3.400000e-07 1.720000e-05 8.280000e-06
                            ]
                          }
                        }
                      }
                    ]
                    name "lf_upper_leg_link"
                    boundingObject Transform {
                      translation 0 0 -0.1
                      rotation 0 1 0 1.570796
                      children [
                        Box {
                          size 0.213000 0.024500 0.034000
                        }
                      ]
                    }
                    physics Physics {
                      density -1
                      mass 1.152000
                      centerOfMass [ -0.003740 -0.022300 -0.032700 ]
                      inertiaMatrix [
                        5.840000e-03 5.800000e-03 1.030000e-03
                        8.720000e-05 -2.890000e-04 8.080000e-04
                      ]
                    }
                  }
                }
              ]
              name "lf_hip_link"
              boundingObject Transform {
                rotation 1 0 0 1.570796
                children [
                  Cylinder {
                    radius 0.046
                    height 0.04
                  }
                ]
              }
              physics Physics {
                density -1
                mass 0.678000
                centerOfMass [ -0.005400 0.001940 -0.000105 ]
                inertiaMatrix [
                  4.800000e-04 8.840000e-04 5.960000e-04
                  -3.010000e-06 1.110000e-06 -1.420000e-06
                ]
              }
            }
          }
          HingeJoint {
            jointParameters HingeJointParameters {
              anchor -0.193400 -0.046500 0.000000
              dampingConstant 0.01
              staticFriction 0.2
            }
            device [
              RotationalMotor {
                name "rh_hip_joint"
                maxVelocity 30.1
                minPosition -1.0472
                maxPosition 1.0472
                maxTorque 23.7
              }
              PositionSensor {
                name "rh_hip_joint_sensor"
              }
            ]
            endPoint Solid {
              translation -0.193400 -0.046500 0.000000
              children [
                Pose {
                  rotation 0.000000 0.000000 -1.000000 3.141593
                  children [
                    USE hip_visual
                  ]
                }
                HingeJoint {
                  jointParameters HingeJointParameters {
                    axis 0.000000 1.000000 0.000000
                    anchor 0.000000 -0.095500 0.000000
                    dampingConstant 0.01
                    staticFriction 0.2
                  }
                  device [
                    RotationalMotor {
                      name "rh_upper_leg_joint"
                      maxVelocity 30.1
                      minPosition -1.5708
                      maxPosition 3.4907
                      maxTorque 23.7
                    }
                    PositionSensor {
                      name "rh_upper_leg_joint_sensor"
                    }
                  ]
                  endPoint Solid {
                    translation 0.000000 -0.095500 0.000000
                    children [
                      USE thigh_mirror_visual
                      HingeJoint {
                        jointParameters HingeJointParameters {
                          position -1.780230
                          axis 0.000000 1.000000 0.000000
                          anchor 0.000000 0.000000 -0.213000
                          dampingConstant 0.01
                          staticFriction 0.2
                        }
                        device [
                          RotationalMotor {
                            name "rh_lower_leg_joint"
                            maxVelocity 20.06
                            minPosition -2.7227
                            maxPosition -0.83776
                            maxTorque 35.55
                          }
                          PositionSensor {
                            name "rh_lower_leg_joint_sensor"
                          }
                        ]
                        endPoint Solid {
                          translation 0.000000 0.000000 -0.213000
                          rotation 0.000000 -1.000000 0.000000 1.780230
                          children [
                            USE calf_visual
                            Solid {
                              translation 0.000000 0.000000 -0.213000
                              children [
                                Shape {
                                  appearance PBRAppearance {
                                    baseColor 0.500000 0.500000 0.500000
                                    roughness 1.000000
                                    metalness 0
                                  }
                                  geometry Sphere {
                                    radius 0.01
                                  }
                                }
                              ]
                              name "rh_foot_link"
                              boundingObject Sphere {
                                radius 0.02
                              }
                              physics Physics {
                                density -1
                                mass 0.060000
                                centerOfMass [ 0.000000 0.000000 0.000000 ]
                                inertiaMatrix [
                                  9.600000e-06 9.600000e-06 9.600000e-06
                                  0.000000e+00 0.000000e+00 0.000000e+00
                                ]
                              }
                            }
                          ]
                          name "rh_lower_leg_link"
                          boundingObject Transform {
                            translation 0 0 -0.1
                            rotation 0 1 0 1.570796
                            children [
                              Box {
                                size 0.213000 0.016000 0.016000
                              }
                            ]
                          }
                          physics Physics {
                            density -1
                            mass 0.154000
                            centerOfMass [ 0.005480 -0.000975 -0.115000 ]
                            inertiaMatrix [
                              1.080000e-03 1.100000e-03 3.290000e-05
                              3.400000e-07 1.720000e-05 8.280000e-06
                            ]
                          }
                        }
                      }
                    ]
                    name "rh_upper_leg_link"
                    boundingObject Transform {
                      translation 0 0 -0.1
                      rotation 0 1 0 1.570796
                      children [
                        Box {
                          size 0.213000 0.024500 0.034000
                        }
                      ]
                    }
                    physics Physics {
                      density -1
                      mass 1.152000
                      centerOfMass [ -0.003740 0.022300 -0.032700 ]
                      inertiaMatrix [
                        5.840000e-03 5.800000e-03 1.030000e-03
                        -8.720000e-05 -2.890000e-04 -8.080000e-04
                      ]
                    }
                  }
                }
              ]
              name "rh_hip_link"
              boundingObject Transform {
                rotation 1 0 0 1.570796
                children [
                  Cylinder {
                    radius 0.046
                    height 0.04
                  }
                ]
              }
              physics Physics {
                density -1
                mass 0.678000
                centerOfMass [ 0.005400 -0.001940 -0.000105 ]
                inertiaMatrix [
                  4.800000e-04 8.840000e-04 5.960000e-04
                  -3.010000e-06 -1.110000e-06 1.420000e-06
                ]
              }
            }
          }
          HingeJoint {
            jointParameters HingeJointParameters {
              anchor -0.193400 0.046500 0.000000
              dampingConstant 0.01
              staticFriction 0.2
            }
            device [
              RotationalMotor {
                name "lh_hip_joint"
                maxVelocity 30.1
                minPosition -1.0472
                maxPosition 1.0472
                maxTorque 23.7
              }
              PositionSensor {
                name "lh_hip_joint_sensor"
              }
            ]
            endPoint Solid {
              translation -0.193400 0.046500 0.000000
              children [
                Pose {
                  rotation 0.000000 1.000000 0.000000 3.141593
                  children [
                    USE hip_visual
                  ]
                }
                HingeJoint {
                  jointParameters HingeJointParameters {
                    axis 0.000000 1.000000 0.000000
                    anchor 0.000000 0.095500 0.000000
                    dampingConstant 0.01
                    staticFriction 0.2
                  }
                  device [
                    RotationalMotor {
                      name "lh_upper_leg_joint"
                      maxVelocity 30.1
                      minPosition -1.5708
                      maxPosition 3.4907
                      maxTorque 23.7
                    }
                    PositionSensor {
                      name "lh_upper_leg_joint_sensor"
                    }
                  ]
                  endPoint Solid {
                    translation 0.000000 0.095500 0.000000
                    children [
                      USE thigh_visual
                      HingeJoint {
                        jointParameters HingeJointParameters {
                          position -1.780230
                          axis 0.000000 1.000000 0.000000
                          anchor 0.000000 0.000000 -0.213000
                          dampingConstant 0.01
                          staticFriction 0.2
                        }
                        device [
                          RotationalMotor {
                            name "lh_lower_leg_joint"
                            maxVelocity 20.06
                            minPosition -2.7227
                            maxPosition -0.83776
                            maxTorque 35.55
                          }
                          PositionSensor {
                            name "lh_lower_leg_joint_sensor"
                          }
                        ]
                        endPoint Solid {
                          translation 0.000000 0.000000 -0.213000
                          rotation 0.000000 -1.000000 0.000000 1.780230
                          children [
                            USE calf_visual
                            Solid {
                              translation 0.000000 0.000000 -0.213000
                              children [
                                Shape {
                                  appearance PBRAppearance {
                                    baseColor 0.500000 0.500000 0.500000
                                    roughness 1.000000
                                    metalness 0
                                  }
                                  geometry Sphere {
                                    radius 0.01
                                  }
                                }
                              ]
                              name "lh_foot_link"
                              boundingObject Sphere {
                                radius 0.02
                              }
                              physics Physics {
                                density -1
                                mass 0.060000
                                centerOfMass [ 0.000000 0.000000 0.000000 ]
                                inertiaMatrix [
                                  9.600000e-06 9.600000e-06 9.600000e-06
                                  0.000000e+00 0.000000e+00 0.000000e+00
                                ]
                              }
                            }
                          ]
                          name "lh_lower_leg_link"
                          boundingObject Transform {
                            translation 0 0 -0.1
                            rotation 0 1 0 1.570796
                            children [
                              Box {
                                size 0.213000 0.016000 0.016000
                              }
                            ]
                          }
                          physics Physics {
                            density -1
                            mass 0.154000
                            centerOfMass [ 0.005480 -0.000975 -0.115000 ]
                            inertiaMatrix [
                              1.080000e-03 1.100000e-03 3.290000e-05
                              3.400000e-07 1.720000e-05 8.280000e-06
                            ]
                          }
                        }
                      }
                    ]
                    name "lh_upper_leg_link"
                    boundingObject Transform {
                      translation 0 0 -0.1
                      rotation 0 1 0 1.570796
                      children [
                        Box {
                          size 0.213000 0.024500 0.034000
                        }
                      ]
                    }
                    physics Physics {
                      density -1
                      mass 1.152000
                      centerOfMass [ -0.003740 -0.022300 -0.032700 ]
                      inertiaMatrix [
                        5.840000e-03 5.800000e-03 1.030000e-03
                        8.720000e-05 -2.890000e-04 8.080000e-04
                      ]
                    }
                  }
                }
              ]
              name "lh_hip_link"
              boundingObject Transform {
                rotation 1 0 0 1.570796
                children [
                  Cylinder {
                    radius 0.046
                    height 0.04
                  }
                ]
              }
              physics Physics {
                density -1
                mass 0.678000
                centerOfMass [ 0.005400 0.001940 -0.000105 ]
                inertiaMatrix [
                  4.800000e-04 8.840000e-04 5.960000e-04
                  3.010000e-06 -1.110000e-06 -1.420000e-06
                ]
              }
            }
          }
        ]
        name "trunk"
        boundingObject Box {
           size 0.376200 0.093500 0.114000
        }
        physics Physics {
          density -1
          mass 6.921000
          centerOfMass [ 0.021112 0.000000 -0.005366 ]
          inertiaMatrix [
            2.448000e-02 9.807700e-02 1.070000e-01
            1.216600e-04 1.484900e-03 -3.120000e-05
          ]
        }
      }
    ]
    name IS name
  }
}
